INFO     root:tests_FD.py:101 FTP
INFO     root:tests_FD.py:101 FTPS
INFO     root:tests_FD.py:109 The server responded with an error. The operation was unsuccessful.
INFO     root:database.py:28 (96, '10.99.13.11', 'wneqa', 'nBhon2VaoHA8Fp8SpXnV+A==', 21, 0, '/wneclient/data/QA/ftp/files/testJakub', None, None, None, None, None, None, None, None, None, None, None, None, None, None, 0, 0, None, None, 0, None, 'tls', None, 'http', 0, None, 'tls', None, 'http', None, None, None, None, None)
INFO     root:database.py:28 (97, '10.60.11.28', 'wneqa', 'BHN2QxnzYfDN9cErkt4/Tw==', 21, 0, '/wneclient/data/QA/ftps/files/ubuntuFTPS', None, None, None, None, None, None, None, None, None, None, None, None, None, None, 0, 0, None, None, 0, 'all', 'tls', 'C', 'http', 0, None, 'tls', None, 'http', None, None, None, None, None)
INFO     root:database.py:28 (98, '10.99.13.11', 'wnecadmin', '65xi1WGc0LEaGGAsKvg7zc5hhes7+M/E+w4dTSTlVLI=', 21, 1, '/wneclient/data/QA/sftp/ubuntuSFTP', None, None, None, None, None, None, None, None, None, None, None, None, None, None, 0, None, None, None, 0, None, 'tls', None, 'http', 0, None, 'tls', None, 'http', None, None, None, None, None)