{"uuid": "a0d206f3-1d2a-446d-b546-146fcab2ce1d", "children": ["4f2bef31-0bcd-426f-9357-d54023397908", "214305a5-98af-4372-9e23-b3a2c8fab561", "409ba1a2-e170-466b-89c3-037cab6b2cca", "e4eeeab4-1817-4a73-9682-7c4b2122bc55", "fd30b015-a45a-4b24-9cf9-6defd49b4283", "9cb120e5-86c8-455b-8065-c8a30309efe0", "72350c1c-e057-48d7-bfe5-04ddef68f589", "42889fc9-3920-4340-8e67-4674276d56aa", "2fccd476-3d8d-454c-90e3-16e912d95b63", "47b57ea4-b80d-4ad4-918d-d76f8e0c178b", "409548fe-f974-4bfc-9707-35df6b2a095b", "47dd342e-0f56-4795-b357-475127d158d9", "2385c3a1-1f8f-40eb-b300-d7cc2052a84c", "b411a981-0d88-45f5-857f-bcef414af06c"], "befores": [{"name": "test_setup", "status": "passed", "start": 1758892666166, "stop": 1758892674974}], "afters": [{"name": "test_setup::0", "status": "broken", "statusDetails": {"message": "requests.exceptions.ConnectionError: HTTPConnectionPool(host='10.189.200.6', port=80): Max retries exceeded with url: /api/v1/authenticate (Caused by NewConnectionError('<urllib3.connection.HTTPConnection object at 0x11378e190>: Failed to establish a new connection: [Errno 51] Network is unreachable'))\n", "trace": "  File \"/Users/s.chethana/PycharmProjects/wnec_backend-automation/.venv/lib/python3.11/site-packages/allure_commons/_allure.py\", line 231, in __call__\n    return self._fixture_function(*args, **kwargs)\n           ^^^^^^^^^^^^^^^^^^^^^^^^^^^^^^^^^^^^^^^\n  File \"/Users/s.chethana/PycharmProjects/wnec_backend-automation/.venv/lib/python3.11/site-packages/_pytest/fixtures.py\", line 911, in _teardown_yield_fixture\n    next(it)\n  File \"/Users/s.chethana/PycharmProjects/Data_Driven_Framework_WNEC/conftest.py\", line 101, in fixture_test_setup\n    FileDistributor().remove_all_disribution_process()\n  File \"/Users/s.chethana/PycharmProjects/Data_Driven_Framework_WNEC/component_util/file_distributor.py\", line 74, in remove_all_disribution_process\n    response, status = API().get(\"/distributionprocesses\")\n                       ^^^^^\n  File \"/Users/s.chethana/PycharmProjects/Data_Driven_Framework_WNEC/helpers/api.py\", line 20, in __init__\n    self.token = get_access_token(username, password)\n                 ^^^^^^^^^^^^^^^^^^^^^^^^^^^^^^^^^^^^\n  File \"/Users/s.chethana/PycharmProjects/Data_Driven_Framework_WNEC/helpers/api.py\", line 12, in get_access_token\n    token_request = requests.post(f\"{API_URL}/authenticate\", json=auth, verify=False, timeout=10)\n                    ^^^^^^^^^^^^^^^^^^^^^^^^^^^^^^^^^^^^^^^^^^^^^^^^^^^^^^^^^^^^^^^^^^^^^^^^^^^^^\n  File \"/Users/s.chethana/PycharmProjects/wnec_backend-automation/.venv/lib/python3.11/site-packages/requests/api.py\", line 115, in post\n    return request(\"post\", url, data=data, json=json, **kwargs)\n           ^^^^^^^^^^^^^^^^^^^^^^^^^^^^^^^^^^^^^^^^^^^^^^^^^^^^\n  File \"/Users/s.chethana/PycharmProjects/wnec_backend-automation/.venv/lib/python3.11/site-packages/requests/api.py\", line 59, in request\n    return session.request(method=method, url=url, **kwargs)\n           ^^^^^^^^^^^^^^^^^^^^^^^^^^^^^^^^^^^^^^^^^^^^^^^^^\n  File \"/Users/s.chethana/PycharmProjects/wnec_backend-automation/.venv/lib/python3.11/site-packages/requests/sessions.py\", line 589, in request\n    resp = self.send(prep, **send_kwargs)\n           ^^^^^^^^^^^^^^^^^^^^^^^^^^^^^^\n  File \"/Users/s.chethana/PycharmProjects/wnec_backend-automation/.venv/lib/python3.11/site-packages/requests/sessions.py\", line 703, in send\n    r = adapter.send(request, **kwargs)\n        ^^^^^^^^^^^^^^^^^^^^^^^^^^^^^^^\n  File \"/Users/s.chethana/PycharmProjects/wnec_backend-automation/.venv/lib/python3.11/site-packages/requests/adapters.py\", line 700, in send\n    raise ConnectionError(e, request=request)\n"}, "start": 1758895245325, "stop": 1758895245327}], "start": 1758892666166, "stop": 1758895245327}